Workbook

Sheet Read me
A1: Photo Finish question bank
A2: Every individual final at the Olympic Games and outdoor World Athletics Championships, 2016 to 2025 (8 championships, 38 events each, 304 finals).
A3: Relays, race walks and combined events are left out. Source: the final results table on each event's Wikipedia page, collected October 2026.
A5: Tabs
A6: Finals: one row per question. The game's answer is the winning mark; the clue is the row named in 'Clue athlete'.
A7: Results: every finisher with a valid mark. Marathons and 10,000 m races with more than 20 finishers list places 1-10 plus the last finisher.
A8: World records: the record going into each championship, plus the records set in these finals.
A9: Review: items a person should check before a question goes live (injured last-place runners, short fields, ties, unclear marks).
A11: What to edit
A12: Yellow cells in the Finals tab ('Verified' and 'Editor note') are for you. Mark Verified = Y once you have checked the final against World Athletics results.
A13: Example: 2024-OG-M100 | Verified: Y | Editor note: Lyles 9.784 vs Thompson 9.789, both shown as 9.79.
A14: Everything else is generated by build.py from the raw files; change the raw files and rebuild rather than editing those cells.

Sheet Finals
A1: ID | B1: Championship | C1: City | D1: Year | E1: Gender | F1: Event | G1: Group | H1: Winner | I1: Country | J1: Winning mark | K1: Clue athlete | L1: Clue place | M1: Clue mark | N1: Finishers listed | O1: Field size | P1: WR going in | Q1: WR holder | R1: WR year | S1: World record set | T1: Review flags | U1: Verified | V1: Editor note
A2: 2016-OG-M400 | B2: Olympic Games | C2: Rio de Janeiro | D2: 2016 | E2: Men | F2: 400 m | G2: sprint | H2: Wayde van Niekerk | I2: RSA | J2: 43.03 | K2: Matthew Hudson-Smith | L2: 8 | M2: 44.61 | N2: =COUNTIF(Results!$A:$A,A2) | O2: 8 | P2: 43.18 | Q2: Michael Johnson | R2: 1999 | S2: Y
A3: 2016-OG-M100 | B3: Olympic Games | C3: Rio de Janeiro | D3: 2016 | E3: Men | F3: 100 m | G3: sprint | H3: Usain Bolt | I3: JAM | J3: 9.81 | K3: Trayvon Bromell | L3: 8 | M3: 10.06 | N3: =COUNTIF(Results!$A:$A,A3) | O3: 8 | P3: 9.58 | Q3: Usain Bolt | R3: 2009
A4: 2016-OG-M200 | B4: Olympic Games | C4: Rio de Janeiro | D4: 2016 | E4: Men | F4: 200 m | G4: sprint | H4: Usain Bolt | I4: JAM | J4: 19.78 | K4: Ramil Guliyev | L4: 8 | M4: 20.43 | N4: =COUNTIF(Results!$A:$A,A4) | O4: 8 | P4: 19.19 | Q4: Usain Bolt | R4: 2009
A5: 2016-OG-M800 | B5: Olympic Games | C5: Rio de Janeiro | D5: 2016 | E5: Men | F5: 800 m | G5: middle | H5: David Rudisha | I5: KEN | J5: 1:42.15 | K5: Boris Berian | L5: 8 | M5: 1:46.15 | N5: =COUNTIF(Results!$A:$A,A5) | O5: 8 | P5: 1:40.91 | Q5: David Rudisha | R5: 2012
A6: 2016-OG-M1500 | B6: Olympic Games | C6: Rio de Janeiro | D6: 2016 | E6: Men | F6: 1500 m | G6: middle | H6: Matthew Centrowitz | I6: USA | J6: 3:50.00 | K6: Charlie Grice | L6: 12 | M6: 3:51.73 | N6: =COUNTIF(Results!$A:$A,A6) | O6: 13 | P6: 3:26.00 | Q6: Hicham El Guerrouj | R6: 1998 | T6: outlier-last
A7: 2016-OG-M5000 | B7: Olympic Games | C7: Rio de Janeiro | D7: 2016 | E7: Men | F7: 5000 m | G7: distance | H7: Mo Farah | I7: GBR | J7: 13:03.30 | K7: David Torrence | L7: 15 | M7: 13:43.12 | N7: =COUNTIF(Results!$A:$A,A7) | O7: 15 | P7: 12:37.35 | Q7: Kenenisa Bekele | R7: 2004
A8: 2016-OG-M10000 | B8: Olympic Games | C8: Rio de Janeiro | D8: 2016 | E8: Men | F8: 10,000 m | G8: distance | H8: Mo Farah | I8: GBR | J8: 27:05.17 | K8: Mohammed Ahmed | L8: 32 | M8: 29:32.84 | N8: =COUNTIF(Results!$A:$A,A8) | O8: 32 | P8: 26:17.53 | Q8: Kenenisa Bekele | R8: 2005
A9: 2016-OG-Mmarathon | B9: Olympic Games | C9: Rio de Janeiro | D9: 2016 | E9: Men | F9: marathon | G9: road | H9: Eliud Kipchoge | I9: KEN | J9: 2:08:44 | K9: Eric Gillis | L9: 10 | M9: 2:12:29 | N9: =COUNTIF(Results!$A:$A,A9) | O9: 139 | P9: 2:02:57 | Q9: Dennis Kimetto | R9: 2014 | T9: partial
A10: 2016-OG-M110H | B10: Olympic Games | C10: Rio de Janeiro | D10: 2016 | E10: Men | F10: 110 m hurdles | G10: hurdles | H10: Omar McLeod | I10: JAM | J10: 13.05 | K10: Milan Trajkovic | L10: 7 | M10: 13.41 | N10: =COUNTIF(Results!$A:$A,A10) | O10: 7 | P10: 12.80 | Q10: Aries Merritt | R10: 2012 | T10: short-field
A11: 2016-OG-M400H | B11: Olympic Games | C11: Rio de Janeiro | D11: 2016 | E11: Men | F11: 400 m hurdles | G11: hurdles | H11: Kerron Clement | I11: USA | J11: 47.73 | K11: Rasmus Mägi | L11: 6 | M11: 48.40 | N11: =COUNTIF(Results!$A:$A,A11) | O11: 7 | P11: 46.78 | Q11: Kevin Young | R11: 1992 | T11: short-field, outlier-last
A12: 2016-OG-M3000SC | B12: Olympic Games | C12: Rio de Janeiro | D12: 2016 | E12: Men | F12: 3000 m steeplechase | G12: distance | H12: Conseslus Kipruto | I12: KEN | J12: 8:03.28 | K12: Yemane Haileselassie | L12: 11 | M12: 8:40.68 | N12: =COUNTIF(Results!$A:$A,A12) | O12: 11 | P12: 7:53.63 | Q12: Saif Saaeed Shaheen | R12: 2004
A13: 2016-OG-MHJ | B13: Olympic Games | C13: Rio de Janeiro | D13: 2016 | E13: Men | F13: high jump | G13: jumps | H13: Derek Drouin | I13: CAN | J13: 2.38 | K13: Brandon Starc | L13: 15 | M13: 2.20 | N13: =COUNTIF(Results!$A:$A,A13) | O13: 15 | P13: 2.45 | Q13: Javier Sotomayor | R13: 1993
A14: 2016-OG-MPV | B14: Olympic Games | C14: Rio de Janeiro | D14: 2016 | E14: Men | F14: pole vault | G14: jumps | H14: Thiago Braz | I14: BRA | J14: 6.03 | K14: Germán Chiaraviglio | L14: 11 | M14: 5.50 | N14: =COUNTIF(Results!$A:$A,A14) | O14: 11 | P14: 6.16 | Q14: Renaud Lavillenie | R14: 2014
A15: 2016-OG-MLJ | B15: Olympic Games | C15: Rio de Janeiro | D15: 2016 | E15: Men | F15: long jump | G15: jumps | H15: Jeff Henderson | I15: USA | J15: 8.38 | K15: Damar Forbes | L15: 12 | M15: 7.82 | N15: =COUNTIF(Results!$A:$A,A15) | O15: 12 | P15: 8.95 | Q15: Mike Powell | R15: 1991
A16: 2016-OG-MTJ | B16: Olympic Games | C16: Rio de Janeiro | D16: 2016 | E16: Men | F16: triple jump | G16: jumps | H16: Christian Taylor | I16: USA | J16: 17.86 | K16: Karol Hoffmann | L16: 12 | M16: 16.31 | N16: =COUNTIF(Results!$A:$A,A16) | O16: 12 | P16: 18.29 | Q16: Jonathan Edwards | R16: 1995
A17: 2016-OG-MSP | B17: Olympic Games | C17: Rio de Janeiro | D17: 2016 | E17: Men | F17: shot put | G17: throws | H17: Ryan Crouser | I17: USA | J17: 22.52 | K17: Stipe Žunić | L17: 11 | M17: 20.04 | N17: =COUNTIF(Results!$A:$A,A17) | O17: 11 | P17: 23.12 | Q17: Randy Barnes | R17: 1990
A18: 2016-OG-MDT | B18: Olympic Games | C18: Rio de Janeiro | D18: 2016 | E18: Men | F18: discus | G18: throws | H18: Christoph Harting | I18: GER | J18: 68.37 | K18: Andrius Gudžius | L18: 12 | M18: 60.66 | N18: =COUNTIF(Results!$A:$A,A18) | O18: 12 | P18: 74.08 | Q18: Jürgen Schult | R18: 1986
A19: 2016-OG-MHT | B19: Olympic Games | C19: Rio de Janeiro | D19: 2016 | E19: Men | F19: hammer | G19: throws | H19: Dilshod Nazarov | I19: TJK | J19: 78.68 | K19: Wagner Domingos | L19: 12 | M19: 72.28 | N19: =COUNTIF(Results!$A:$A,A19) | O19: 12 | P19: 86.74 | Q19: Yuriy Sedykh | R19: 1986
A20: 2016-OG-MJT | B20: Olympic Games | C20: Rio de Janeiro | D20: 2016 | E20: Men | F20: javelin | G20: throws | H20: Thomas Röhler | I20: GER | J20: 90.30 | K20: Petr Frydrych | L20: 12 | M20: 79.12 | N20: =COUNTIF(Results!$A:$A,A20) | O20: 12 | P20: 98.48 | Q20: Jan Železný | R20: 1996
A21: 2016-OG-W100 | B21: Olympic Games | C21: Rio de Janeiro | D21: 2016 | E21: Women | F21: 100 m | G21: sprint | H21: Elaine Thompson | I21: JAM | J21: 10.71 | K21: English Gardner | L21: 7 | M21: 10.94 | N21: =COUNTIF(Results!$A:$A,A21) | O21: 8 | P21: 10.49 | Q21: Florence Griffith-Joyner | R21: 1988 | T21: outlier-last
A22: 2016-OG-W200 | B22: Olympic Games | C22: Rio de Janeiro | D22: 2016 | E22: Women | F22: 200 m | G22: sprint | H22: Elaine Thompson | I22: JAM | J22: 21.78 | K22: Ivet Lalova-Collio | L22: 8 | M22: 22.69 | N22: =COUNTIF(Results!$A:$A,A22) | O22: 8 | P22: 21.34 | Q22: Florence Griffith-Joyner | R22: 1988
A23: 2016-OG-W400 | B23: Olympic Games | C23: Rio de Janeiro | D23: 2016 | E23: Women | F23: 400 m | G23: sprint | H23: Shaunae Miller | I23: BAH | J23: 49.44 | K23: Libania Grenot | L23: 7 | M23: 51.25 | N23: =COUNTIF(Results!$A:$A,A23) | O23: 7 | P23: 47.60 | Q23: Marita Koch | R23: 1985 | T23: short-field
A24: 2016-OG-W800 | B24: Olympic Games | C24: Rio de Janeiro | D24: 2016 | E24: Women | F24: 800 m | G24: middle | H24: Caster Semenya | I24: RSA | J24: 1:55.28 | K24: Kate Grace | L24: 8 | M24: 1:59.57 | N24: =COUNTIF(Results!$A:$A,A24) | O24: 8 | P24: 1:53.28 | Q24: Jarmila Kratochvílová | R24: 1983
A25: 2016-OG-W1500 | B25: Olympic Games | C25: Rio de Janeiro | D25: 2016 | E25: Women | F25: 1500 m | G25: middle | H25: Faith Kipyegon | I25: KEN | J25: 4:08.92 | K25: Rababe Arafi | L25: 12 | M25: 4:15.16 | N25: =COUNTIF(Results!$A:$A,A25) | O25: 12 | P25: 3:50.07 | Q25: Genzebe Dibaba | R25: 2015
A26: 2016-OG-W5000 | B26: Olympic Games | C26: Rio de Janeiro | D26: 2016 | E26: Women | F26: 5000 m | G26: distance | H26: Vivian Cheruiyot | I26: KEN | J26: 14:26.17 | K26: Nikki Hamblin | L26: 17 | M26: 16:14.24 | N26: =COUNTIF(Results!$A:$A,A26) | O26: 17 | P26: 14:11.15 | Q26: Tirunesh Dibaba | R26: 2008
A27: 2016-OG-W10000 | B27: Olympic Games | C27: Rio de Janeiro | D27: 2016 | E27: Women | F27: 10,000 m | G27: distance | H27: Almaz Ayana | I27: ETH | J27: 29:17.45 | K27: Eloise Wellings | L27: 10 | M27: 31:14.94 | N27: =COUNTIF(Results!$A:$A,A27) | O27: 35 | P27: 29:31.78 | Q27: Wang Junxia | R27: 1993 | S27: Y | T27: partial
A28: 2016-OG-Wmarathon | B28: Olympic Games | C28: Rio de Janeiro | D28: 2016 | E28: Women | F28: marathon | G28: road | H28: Jemima Sumgong | I28: KEN | J28: 2:24:04 | K28: Kim Hye-song | L28: 10 | M28: 2:28:36 | N28: =COUNTIF(Results!$A:$A,A28) | O28: 133 | P28: 2:15:25 | Q28: Paula Radcliffe | R28: 2003 | T28: partial
A29: 2016-OG-W100H | B29: Olympic Games | C29: Rio de Janeiro | D29: 2016 | E29: Women | F29: 100 m hurdles | G29: hurdles | H29: Brianna Rollins | I29: USA | J29: 12.48 | K29: Phylicia George | L29: 8 | M29: 12.89 | N29: =COUNTIF(Results!$A:$A,A29) | O29: 8 | P29: 12.20 | Q29: Kendra Harrison | R29: 2016 | T29: check-mark
A30: 2016-OG-W400H | B30: Olympic Games | C30: Rio de Janeiro | D30: 2016 | E30: Women | F30: 400 m hurdles | G30: hurdles | H30: Dalilah Muhammad | I30: USA | J30: 53.13 | K30: Eilidh Doyle | L30: 8 | M30: 54.61 | N30: =COUNTIF(Results!$A:$A,A30) | O30: 8 | P30: 52.34 | Q30: Yuliya Pechonkina | R30: 2003
A31: 2016-OG-W3000SC | B31: Olympic Games | C31: Rio de Janeiro | D31: 2016 | E31: Women | F31: 3000 m steeplechase | G31: distance | H31: Ruth Jebet | I31: BRN | J31: 8:59.75 | K31: Fabienne Schlumpf | L31: 18 | M31: 9:59.30 | N31: =COUNTIF(Results!$A:$A,A31) | O31: 18 | P31: 8:58.81 | Q31: Gulnara Galkina | R31: 2008
A32: 2016-OG-WHJ | B32: Olympic Games | C32: Rio de Janeiro | D32: 2016 | E32: Women | F32: high jump | G32: jumps | H32: Ruth Beitia | I32: ESP | J32: 1.97 | K32: Alyxandria Treasure | L32: 17 | M32: 1.88 | N32: =COUNTIF(Results!$A:$A,A32) | O32: 17 | P32: 2.09 | Q32: Stefka Kostadinova | R32: 1987
A33: 2016-OG-WPV | B33: Olympic Games | C33: Rio de Janeiro | D33: 2016 | E33: Women | F33: pole vault | G33: jumps | H33: Katerina Stefanidi | I33: GRE | J33: 4.85 | K33: Kelsie Ahbe | L33: 12 | M33: 4.50 | N33: =COUNTIF(Results!$A:$A,A33) | O33: 12 | P33: 5.06 | Q33: Yelena Isinbayeva | R33: 2009
A34: 2016-OG-WLJ | B34: Olympic Games | C34: Rio de Janeiro | D34: 2016 | E34: Women | F34: long jump | G34: jumps | H34: Tianna Bartoletta | I34: USA | J34: 7.17 | K34: Lorraine Ugen | L34: 11 | M34: 6.58 | N34: =COUNTIF(Results!$A:$A,A34) | O34: 11 | P34: 7.52 | Q34: Galina Chistyakova | R34: 1988
A35: 2016-OG-WTJ | B35: Olympic Games | C35: Rio de Janeiro | D35: 2016 | E35: Women | F35: triple jump | G35: jumps | H35: Caterine Ibargüen | I35: COL | J35: 15.17 | K35: Kristiina Mäkelä | L35: 12 | M35: 13.95 | N35: =COUNTIF(Results!$A:$A,A35) | O35: 12 | P35: 15.50 | Q35: Inessa Kravets | R35: 1995
A36: 2016-OG-WSP | B36: Olympic Games | C36: Rio de Janeiro | D36: 2016 | E36: Women | F36: shot put | G36: throws | H36: Michelle Carter | I36: USA | J36: 20.63 | K36: Auriole Dongmo | L36: 12 | M36: 16.99 | N36: =COUNTIF(Results!$A:$A,A36) | O36: 12 | P36: 22.63 | Q36: Natalya Lisovskaya | R36: 1987
A37: 2016-OG-WDT | B37: Olympic Games | C37: Rio de Janeiro | D37: 2016 | E37: Women | F37: discus | G37: throws | H37: Sandra Perković | I37: CRO | J37: 69.21 | K37: Shanice Craft | L37: 11 | M37: 59.85 | N37: =COUNTIF(Results!$A:$A,A37) | O37: 11 | P37: 76.80 | Q37: Gabriele Reinsch | R37: 1988
A38: 2016-OG-WHT | B38: Olympic Games | C38: Rio de Janeiro | D38: 2016 | E38: Women | F38: hammer | G38: throws | H38: Anita Włodarczyk | I38: POL | J38: 82.29 | K38: Alexandra Tavernier | L38: 11 | M38: 65.18 | N38: =COUNTIF(Results!$A:$A,A38) | O38: 11 | P38: 81.08 | Q38: Anita Włodarczyk | R38: 2015 | S38: Y
A39: 2016-OG-WJT | B39: Olympic Games | C39: Rio de Janeiro | D39: 2016 | E39: Women | F39: javelin | G39: throws | H39: Sara Kolak | I39: CRO | J39: 66.18 | K39: Christin Hussong | L39: 12 | M39: 57.70 | N39: =COUNTIF(Results!$A:$A,A39) | O39: 12 | P39: 72.28 | Q39: Barbora Špotáková | R39: 2008
A40: 2017-WC-M100 | B40: World Championships | C40: London | D40: 2017 | E40: Men | F40: 100 m | G40: sprint | H40: Justin Gatlin | I40: USA | J40: 9.92 | K40: Su Bingtian | L40: 8 | M40: 10.27 | N40: =COUNTIF(Results!$A:$A,A40) | O40: 8 | P40: 9.58 | Q40: Usain Bolt | R40: 2009
...

Sheet Results
A1: Final ID | B1: Place | C1: Athlete | D1: Country | E1: Mark | F1: Value (s or m)
A2: 2016-OG-M400 | B2: 1 | C2: Wayde van Niekerk | D2: RSA | E2: 43.03 | F2: 43.03
A3: 2016-OG-M400 | B3: 2 | C3: Kirani James | D3: GRN | E3: 43.76 | F3: 43.76
A4: 2016-OG-M400 | B4: 3 | C4: LaShawn Merritt | D4: USA | E4: 43.85 | F4: 43.85
A5: 2016-OG-M400 | B5: 4 | C5: Machel Cedenio | D5: TTO | E5: 44.01 | F5: 44.01
A6: 2016-OG-M400 | B6: 5 | C6: Karabo Sibanda | D6: BOT | E6: 44.25 | F6: 44.25
A7: 2016-OG-M400 | B7: 6 | C7: Ali Khamis | D7: BRN | E7: 44.36 | F7: 44.36
A8: 2016-OG-M400 | B8: 7 | C8: Bralon Taplin | D8: GRN | E8: 44.45 | F8: 44.45
A9: 2016-OG-M400 | B9: 8 | C9: Matthew Hudson-Smith | D9: GBR | E9: 44.61 | F9: 44.61
A10: 2016-OG-M100 | B10: 1 | C10: Usain Bolt | D10: JAM | E10: 9.81 | F10: 9.81
A11: 2016-OG-M100 | B11: 2 | C11: Justin Gatlin | D11: USA | E11: 9.89 | F11: 9.89
A12: 2016-OG-M100 | B12: 3 | C12: Andre De Grasse | D12: CAN | E12: 9.91 | F12: 9.91
A13: 2016-OG-M100 | B13: 4 | C13: Yohan Blake | D13: JAM | E13: 9.93 | F13: 9.93
... A3360: 2025-WC-WJT | B3360: 12 | C3360: Małgorzata Maślak-Glugla | D3360: POL | E3360: 57.80 | F3360: 57.8

Sheet World records
A1: Event | B1: Mark | C1: Holder | D1: Year | E1: Going into | F1: Set in final
A2: Men's 400 m | B2: 43.18 | C2: Michael Johnson | D2: 1999 | E2: 2016-OG-M400
A3: Men's 400 m | B3: 43.03 | C3: Wayde van Niekerk | D3: 2016 | E3: 2017-WC-M400, 2019-WC-M400, 2020-OG-M400, 2022-WC-M400, 2023-WC-M400, 2024-OG-M400, 2025-WC-M400 | F3: 2016-OG-M400
A4: Men's 100 m | B4: 9.58 | C4: Usain Bolt | D4: 2009 | E4: 2016-OG-M100, 2017-WC-M100, 2019-WC-M100, 2020-OG-M100, 2022-WC-M100, 2023-WC-M100, 2024-OG-M100, 2025-WC-M100
A5: Men's 200 m | B5: 19.19 | C5: Usain Bolt | D5: 2009 | E5: 2016-OG-M200, 2017-WC-M200, 2019-WC-M200, 2020-OG-M200, 2022-WC-M200, 2023-WC-M200, 2024-OG-M200, 2025-WC-M200
A6: Men's 800 m | B6: 1:40.91 | C6: David Rudisha | D6: 2012 | E6: 2016-OG-M800, 2017-WC-M800, 2019-WC-M800, 2020-OG-M800, 2022-WC-M800, 2023-WC-M800, 2024-OG-M800, 2025-WC-M800
A7: Men's 1500 m | B7: 3:26.00 | C7: Hicham El Guerrouj | D7: 1998 | E7: 2016-OG-M1500, 2017-WC-M1500, 2019-WC-M1500, 2020-OG-M1500, 2022-WC-M1500, 2023-WC-M1500, 2024-OG-M1500, 2025-WC-M1500
A8: Men's 5000 m | B8: 12:37.35 | C8: Kenenisa Bekele | D8: 2004 | E8: 2016-OG-M5000, 2017-WC-M5000, 2019-WC-M5000
A9: Men's 5000 m | B9: 12:35.36 | C9: Joshua Cheptegei | D9: 2020 | E9: 2020-OG-M5000, 2022-WC-M5000, 2023-WC-M5000, 2024-OG-M5000, 2025-WC-M5000
A10: Men's 10,000 m | B10: 26:17.53 | C10: Kenenisa Bekele | D10: 2005 | E10: 2016-OG-M10000, 2017-WC-M10000, 2019-WC-M10000
A11: Men's 10,000 m | B11: 26:11.00 | C11: Joshua Cheptegei | D11: 2020 | E11: 2020-OG-M10000, 2022-WC-M10000, 2023-WC-M10000, 2024-OG-M10000, 2025-WC-M10000
A12: Men's marathon | B12: 2:02:57 | C12: Dennis Kimetto | D12: 2014 | E12: 2016-OG-Mmarathon, 2017-WC-Mmarathon
A13: Men's marathon | B13: 2:01:39 | C13: Eliud Kipchoge | D13: 2018 | E13: 2019-WC-Mmarathon, 2020-OG-Mmarathon, 2022-WC-Mmarathon
A14: Men's marathon | B14: 2:01:09 | C14: Eliud Kipchoge | D14: 2022 | E14: 2023-WC-Mmarathon
A15: Men's marathon | B15: 2:00:35 | C15: Kelvin Kiptum | D15: 2023 | E15: 2024-OG-Mmarathon, 2025-WC-Mmarathon
... A18: Men's 400 m hurdles | B18: 46.70 | C18: Karsten Warholm | D18: 2021 | E18: 2020-OG-M400H
A19: Men's 400 m hurdles | B19: 45.94 | C19: Karsten Warholm | D19: 2021 | E19: 2022-WC-M400H, 2023-WC-M400H, 2024-OG-M400H, 2025-WC-M400H | F19: 2020-OG-M400H
A20: Men's 3000 m steeplechase | B20: 7:53.63 | C20: Saif Saaeed Shaheen | D20: 2004 | E20: 2016-OG-M3000SC, 2017-WC-M3000SC, 2019-WC-M3000SC, 2020-OG-M3000SC, 2022-WC-M3000SC
A21: Men's 3000 m steeplechase | B21: 7:52.11 | C21: Lamecha Girma | D21: 2023 | E21: 2023-WC-M3000SC, 2024-OG-M3000SC, 2025-WC-M3000SC
A22: Men's high jump | B22: 2.45 | C22: Javier Sotomayor | D22: 1993 | E22: 2016-OG-MHJ, 2017-WC-MHJ, 2019-WC-MHJ, 2020-OG-MHJ, 2022-WC-MHJ, 2023-WC-MHJ, 2024-OG-MHJ, 2025-WC-MHJ
A23: Men's pole vault | B23: 6.16 | C23: Renaud Lavillenie | D23: 2014 | E23: 2016-OG-MPV, 2017-WC-MPV, 2019-WC-MPV
A24: Men's pole vault | B24: 6.18 | C24: Armand Duplantis | D24: 2020 | E24: 2020-OG-MPV
A25: Men's pole vault | B25: 6.20 | C25: Armand Duplantis | D25: 2022 | E25: 2022-WC-MPV
A26: Men's pole vault | B26: 6.21 | C26: Armand Duplantis | D26: 2022 | F26: 2022-WC-MPV
A27: Men's pole vault | B27: 6.22 | C27: Armand Duplantis | D27: 2023 | E27: 2023-WC-MPV
A28: Men's pole vault | B28: 6.24 | C28: Armand Duplantis | D28: 2024 | E28: 2024-OG-MPV
A29: Men's pole vault | B29: 6.25 | C29: Armand Duplantis | D29: 2024 | F29: 2024-OG-MPV
A30: Men's pole vault | B30: 6.29 | C30: Armand Duplantis | D30: 2025 | E30: 2025-WC-MPV
A31: Men's pole vault | B31: 6.30 | C31: Armand Duplantis | D31: 2025 | F31: 2025-WC-MPV
A32: Men's long jump | B32: 8.95 | C32: Mike Powell | D32: 1991 | E32: 2016-OG-MLJ, 2017-WC-MLJ, 2019-WC-MLJ, 2020-OG-MLJ, 2022-WC-MLJ, 2023-WC-MLJ, 2024-OG-MLJ, 2025-WC-MLJ
A33: Men's triple jump | B33: 18.29 | C33: Jonathan Edwards | D33: 1995 | E33: 2016-OG-MTJ, 2017-WC-MTJ, 2019-WC-MTJ, 2020-OG-MTJ, 2022-WC-MTJ, 2023-WC-MTJ, 2024-OG-MTJ, 2025-WC-MTJ
A34: Men's shot put | B34: 23.12 | C34: Randy Barnes | D34: 1990 | E34: 2016-OG-MSP, 2017-WC-MSP, 2019-WC-MSP
A35: Men's shot put | B35: 23.37 | C35: Ryan Crouser | D35: 2021 | E35: 2020-OG-MSP, 2022-WC-MSP
A36: Men's shot put | B36: 23.56 | C36: Ryan Crouser | D36: 2023 | E36: 2023-WC-MSP, 2024-OG-MSP, 2025-WC-MSP
A37: Men's discus | B37: 74.08 | C37: Jürgen Schult | D37: 1986 | E37: 2016-OG-MDT, 2017-WC-MDT, 2019-WC-MDT, 2020-OG-MDT, 2022-WC-MDT, 2023-WC-MDT
A38: Men's discus | B38: 74.35 | C38: Mykolas Alekna | D38: 2024 | E38: 2024-OG-MDT
A39: Men's discus | B39: 75.56 | C39: Mykolas Alekna | D39: 2025 | E39: 2025-WC-MDT
A40: Men's hammer | B40: 86.74 | C40: Yuriy Sedykh | D40: 1986 | E40: 2016-OG-MHT, 2017-WC-MHT, 2019-WC-MHT, 2020-OG-MHT, 2022-WC-MHT, 2023-WC-MHT, 2024-OG-MHT, 2025-WC-MHT
A41: Men's javelin | B41: 98.48 | C41: Jan Železný | D41: 1996 | E41: 2016-OG-MJT, 2017-WC-MJT, 2019-WC-MJT, 2020-OG-MJT, 2022-WC-MJT, 2023-WC-MJT, 2024-OG-MJT, 2025-WC-MJT
A42: Women's 100 m | B42: 10.49 | C42: Florence Griffith-Joyner | D42: 1988 | E42: 2016-OG-W100, 2017-WC-W100, 2019-WC-W100, 2020-OG-W100, 2022-WC-W100, 2023-WC-W100, 2024-OG-W100, 2025-WC-W100
...

Sheet Review
A1: Final ID | B1: Issue | C1: Note | D1: Resolved
A2: 2016-OG-M1500 | B2: outlier-last | C2: Ronald Kwemoi 3:56.76 far behind; clue uses Charlie Grice 3:51.73
A3: 2016-OG-M110H | B3: short-field | C3: only 7 finishers with a time
A4: 2016-OG-M400H | B4: short-field | C4: only 7 finishers with a time
A5: 2016-OG-M400H | B5: outlier-last | C5: Haron Koech 49.09 far behind; clue uses Rasmus Mägi 48.40
A6: 2016-OG-W100 | B6: outlier-last | C6: Christania Williams 11.80 far behind; clue uses English Gardner 10.94
A7: 2016-OG-W400 | B7: short-field | C7: only 7 finishers with a time
A8: 2016-OG-W100H | B8: check-mark | C8: a mark was unclear on the source page
A9: 2017-WC-M5000 | B9: outlier-last | C9: Awet Habte 13:58.68 far behind; clue uses Cyrus Rutto 13:48.64
A10: 2017-WC-M400 | B10: short-field | C10: only 7 finishers with a time
A11: 2017-WC-M3000SC | B11: outlier-last | C11: Jacob Araptany 8:49.18 far behind; clue uses Yoann Kowal 8:34.53
A12: 2017-WC-MSP | B12: outlier-last | C12: Andrei Gag 19.96 far behind; clue uses Darrell Hill 20.79
A13: 2017-WC-W200 | B13: outlier-last | C13: Tynia Gaither 23.07 far behind; clue uses Crystal Emmanuel 22.60
... A65: 2025-WC-W1500 | B65: outlier-last | C65: Nele Weßel 4:10.31 far behind; clue uses Sinclaire Johnson 4:00.92
